Workbook

Sheet 가정_및_설정
A1: 항목 | B1: 값 | C1: 비고
A2: S3(화장실) 임시 기본값 | B2: 50 | C2: 실측 데이터 0건 - 사용자 지정값(중간값 가정)
A3: S4(엘리베이터) 임시 기본값 | B3: 50 | C3: 실측 데이터 0건 - 사용자 지정값(중간값 가정)
A4: S5(주차장) 임시 기본값 | B4: 50 | C4: 실측 데이터 0건 - 사용자 지정값(중간값 가정)
A6: ※ 현장답사 데이터 시트에는 '보행로'(S1), '출입구'(S2) 실측값만 존재합니다.
A7: 화장실/엘리베이터/주차장(S3~S5)은 실측치가 전혀 없어 6단계의 '전체 평균(Global Mean) 대입'조차 불가능하므로,
A8: 사용자 지정에 따라 위 임시 기본값(50점)을 모든 구역에 동일하게 대입하여 5각형 공식을 유지합니다.

Sheet S1_보행로
A1: ID | B1: 장소명 | C1: GPS | D1: 구역 | E1: 유효폭_5m이상 | F1: 유효폭(m) | G1: 단차(cm) | H1: 기울기(도) | I1: x1_유효폭(cm) | J1: s1_유효폭점수 | K1: s2_단차점수 | L1: s3_기울기점수 | M1: S1_보행로지수
A2: b198d9ab | B2: kt대리점 | C2: 35.176439, 126.912489 | D2: 3 | E2: =FALSE() -> FALSE | F2: 1.69 | G2: 0 | H2: 0 | I2: =IF(F2<>"",F2*100,IF(E2=TRUE(),500,"")) -> 169 | J2: =IF(I2="","",MIN(100,MAX(0,(I2-40)/(120-40)*100))) -> 100 | K2: =IF(G2="","",MIN(100,MAX(0,(6-G2)/(6-2)*100))) -> 100 | L2: =IF(H2="","",MIN(100,MAX(0,(14.4-H2)/(14.4-4.8)*100))) -> 100 | M2: =IFERROR(AVERAGE(J2:L2),"") -> 100
A3: 04fcf078 | B3: 스타벅스 전남대점 | C3: 35.177230, 126.912376 | D3: 1 | E3: =FALSE() -> FALSE | F3: 1.63 | G3: 0 | H3: 0 | I3: =IF(F3<>"",F3*100,IF(E3=TRUE(),500,"")) -> 163 | J3: =IF(I3="","",MIN(100,MAX(0,(I3-40)/(120-40)*100))) -> 100 | K3: =IF(G3="","",MIN(100,MAX(0,(6-G3)/(6-2)*100))) -> 100 | L3: =IF(H3="","",MIN(100,MAX(0,(14.4-H3)/(14.4-4.8)*100))) -> 100 | M3: =IFERROR(AVERAGE(J3:L3),"") -> 100
A4: 4d73e46a | B4: 올리브 | C4: 35.176479, 126.913793 | D4: 4 | E4: =TRUE() -> TRUE | G4: 0 | H4: 2.1 | I4: =IF(F4<>"",F4*100,IF(E4=TRUE(),500,"")) -> 500 | J4: =IF(I4="","",MIN(100,MAX(0,(I4-40)/(120-40)*100))) -> 100 | K4: =IF(G4="","",MIN(100,MAX(0,(6-G4)/(6-2)*100))) -> 100 | L4: =IF(H4="","",MIN(100,MAX(0,(14.4-H4)/(14.4-4.8)*100))) -> 100 | M4: =IFERROR(AVERAGE(J4:L4),"") -> 100
A5: 667e9b13 | B5: 포토그레이 | C5: 35.175493, 126.912793 | D5: 3 | E5: =TRUE() -> TRUE | G5: 0 | H5: 1.2 | I5: =IF(F5<>"",F5*100,IF(E5=TRUE(),500,"")) -> 500 | J5: =IF(I5="","",MIN(100,MAX(0,(I5-40)/(120-40)*100))) -> 100 | K5: =IF(G5="","",MIN(100,MAX(0,(6-G5)/(6-2)*100))) -> 100 | L5: =IF(H5="","",MIN(100,MAX(0,(14.4-H5)/(14.4-4.8)*100))) -> 100 | M5: =IFERROR(AVERAGE(J5:L5),"") -> 100
A6: e5095747 | B6: OH! CREPE | C6: 35.176436, 126.913098 | D6: 3 | E6: =TRUE() -> TRUE | G6: 0 | H6: 3.2 | I6: =IF(F6<>"",F6*100,IF(E6=TRUE(),500,"")) -> 500 | J6: =IF(I6="","",MIN(100,MAX(0,(I6-40)/(120-40)*100))) -> 100 | K6: =IF(G6="","",MIN(100,MAX(0,(6-G6)/(6-2)*100))) -> 100 | L6: =IF(H6="","",MIN(100,MAX(0,(14.4-H6)/(14.4-4.8)*100))) -> 100 | M6: =IFERROR(AVERAGE(J6:L6),"") -> 100
A7: 5fcbcb0e | B7: 아트박스 | C7: 35.175514, 126.913066 | D7: 3 | E7: =TRUE() -> TRUE | G7: 0 | H7: 1.4 | I7: =IF(F7<>"",F7*100,IF(E7=TRUE(),500,"")) -> 500 | J7: =IF(I7="","",MIN(100,MAX(0,(I7-40)/(120-40)*100))) -> 100 | K7: =IF(G7="","",MIN(100,MAX(0,(6-G7)/(6-2)*100))) -> 100 | L7: =IF(H7="","",MIN(100,MAX(0,(14.4-H7)/(14.4-4.8)*100))) -> 100 | M7: =IFERROR(AVERAGE(J7:L7),"") -> 100
A8: 5506da05 | B8: 고수닭갈비 | C8: 35.176872, 126.913312 | D8: 1 | E8: =FALSE() -> FALSE | F8: 1.3 | G8: 0 | H8: 8.8 | I8: =IF(F8<>"",F8*100,IF(E8=TRUE(),500,"")) -> 130 | J8: =IF(I8="","",MIN(100,MAX(0,(I8-40)/(120-40)*100))) -> 100 | K8: =IF(G8="","",MIN(100,MAX(0,(6-G8)/(6-2)*100))) -> 100 | L8: =IF(H8="","",MIN(100,MAX(0,(14.4-H8)/(14.4-4.8)*100))) -> 58.333333 | M8: =IFERROR(AVERAGE(J8:L8),"") -> 86.111111
A9: 74977598 | B9: 포토이즘 | C9: 35.175586, 126.913125 | D9: 3 | E9: =TRUE() -> TRUE | G9: 0 | H9: 3.4 | I9: =IF(F9<>"",F9*100,IF(E9=TRUE(),500,"")) -> 500 | J9: =IF(I9="","",MIN(100,MAX(0,(I9-40)/(120-40)*100))) -> 100 | K9: =IF(G9="","",MIN(100,MAX(0,(6-G9)/(6-2)*100))) -> 100 | L9: =IF(H9="","",MIN(100,MAX(0,(14.4-H9)/(14.4-4.8)*100))) -> 100 | M9: =IFERROR(AVERAGE(J9:L9),"") -> 100
A10: 5f15ef5a | B10: 벌툰 | C10: 35.176911, 126.913460 | D10: 1 | E10: =FALSE() -> FALSE | F10: 1.2 | G10: 4 | H10: 11.2 | I10: =IF(F10<>"",F10*100,IF(E10=TRUE(),500,"")) -> 120 | J10: =IF(I10="","",MIN(100,MAX(0,(I10-40)/(120-40)*100))) -> 100 | K10: =IF(G10="","",MIN(100,MAX(0,(6-G10)/(6-2)*100))) -> 50 | L10: =IF(H10="","",MIN(100,MAX(0,(14.4-H10)/(14.4-4.8)*100))) -> 33.333333 | M10: =IFERROR(AVERAGE(J10:L10),"") -> 61.111111
A11: 2fad83d8 | B11: 베타 미용도소매점 | C11: 35.176833, 126.913124 | D11: 1 | E11: =TRUE() -> TRUE | G11: 0 | H11: 0 | I11: =IF(F11<>"",F11*100,IF(E11=TRUE(),500,"")) -> 500 | J11: =IF(I11="","",MIN(100,MAX(0,(I11-40)/(120-40)*100))) -> 100 | K11: =IF(G11="","",MIN(100,MAX(0,(6-G11)/(6-2)*100))) -> 100 | L11: =IF(H11="","",MIN(100,MAX(0,(14.4-H11)/(14.4-4.8)*100))) -> 100 | M11: =IFERROR(AVERAGE(J11:L11),"") -> 100
A12: 893dd380 | B12: 마장동 고기집 | C12: 35.176397, 126.914525 | D12: 4 | E12: =TRUE() -> TRUE | G12: 0 | H12: 4.1 | I12: =IF(F12<>"",F12*100,IF(E12=TRUE(),500,"")) -> 500 | J12: =IF(I12="","",MIN(100,MAX(0,(I12-40)/(120-40)*100))) -> 100 | K12: =IF(G12="","",MIN(100,MAX(0,(6-G12)/(6-2)*100))) -> 100 | L12: =IF(H12="","",MIN(100,MAX(0,(14.4-H12)/(14.4-4.8)*100))) -> 100 | M12: =IFERROR(AVERAGE(J12:L12),"") -> 100
A13: bb60e692 | B13: 용흥경로당 | C13: 35.176417, 126.913912 | D13: 4 | E13: =FALSE() -> FALSE | F13: 1.73 | G13: 1 | H13: 2.4 | I13: =IF(F13<>"",F13*100,IF(E13=TRUE(),500,"")) -> 173 | J13: =IF(I13="","",MIN(100,MAX(0,(I13-40)/(120-40)*100))) -> 100 | K13: =IF(G13="","",MIN(100,MAX(0,(6-G13)/(6-2)*100))) -> 100 | L13: =IF(H13="","",MIN(100,MAX(0,(14.4-H13)/(14.4-4.8)*100))) -> 100 | M13: =IFERROR(AVERAGE(J13:L13),"") -> 100
A14: 10644145 | B14: 스타노래연습장 | C14: 35.176484, 126.913868 | D14: 4 | E14: =TRUE() -> TRUE | G14: 0 | H14: 0 | I14: =IF(F14<>"",F14*100,IF(E14=TRUE(),500,"")) -> 500 | J14: =IF(I14="","",MIN(100,MAX(0,(I14-40)/(120-40)*100))) -> 100 | K14: =IF(G14="","",MIN(100,MAX(0,(6-G14)/(6-2)*100))) -> 100 | L14: =IF(H14="","",MIN(100,MAX(0,(14.4-H14)/(14.4-4.8)*100))) -> 100 | M14: =IFERROR(AVERAGE(J14:L14),"") -> 100
A15: 48fa3c8b | B15: 더맥소 | C15: 35.176505, 126.914203 | D15: 2 | E15: =TRUE() -> TRUE | G15: 0 | H15: 0 | I15: =IF(F15<>"",F15*100,IF(E15=TRUE(),500,"")) -> 500 | J15: =IF(I15="","",MIN(100,MAX(0,(I15-40)/(120-40)*100))) -> 100 | K15: =IF(G15="","",MIN(100,MAX(0,(6-G15)/(6-2)*100))) -> 100 | L15: =IF(H15="","",MIN(100,MAX(0,(14.4-H15)/(14.4-4.8)*100))) -> 100 | M15: =IFERROR(AVERAGE(J15:L15),"") -> 100
A16: 9e46ace6 | B16: 효자동솥뚜껑 | C16: 35.176506, 126.913541 | D16: 2 | E16: =TRUE() -> TRUE | G16: 0 | H16: 4.8 | I16: =IF(F16<>"",F16*100,IF(E16=TRUE(),500,"")) -> 500 | J16: =IF(I16="","",MIN(100,MAX(0,(I16-40)/(120-40)*100))) -> 100 | K16: =IF(G16="","",MIN(100,MAX(0,(6-G16)/(6-2)*100))) -> 100 | L16: =IF(H16="","",MIN(100,MAX(0,(14.4-H16)/(14.4-4.8)*100))) -> 100 | M16: =IFERROR(AVERAGE(J16:L16),"") -> 100
A17: 8da1c20d | B17: 매머드커피 | C17: 35.176781, 126.912518 | D17: 1 | E17: =TRUE() -> TRUE | G17: 0 | H17: 11 | I17: =IF(F17<>"",F17*100,IF(E17=TRUE(),500,"")) -> 500 | J17: =IF(I17="","",MIN(100,MAX(0,(I17-40)/(120-40)*100))) -> 100 | K17: =IF(G17="","",MIN(100,MAX(0,(6-G17)/(6-2)*100))) -> 100 | L17: =IF(H17="","",MIN(100,MAX(0,(14.4-H17)/(14.4-4.8)*100))) -> 35.416667 | M17: =IFERROR(AVERAGE(J17:L17),"") -> 78.472222
A18: 58be58cf | B18: 김금자숯불갈비 | C18: 35.177434, 126.914322 | D18: 2 | E18: =TRUE() -> TRUE | G18: 2 | H18: 0 | I18: =IF(F18<>"",F18*100,IF(E18=TRUE(),500,"")) -> 500 | J18: =IF(I18="","",MIN(100,MAX(0,(I18-40)/(120-40)*100))) -> 100 | K18: =IF(G18="","",MIN(100,MAX(0,(6-G18)/(6-2)*100))) -> 100 | L18: =IF(H18="","",MIN(100,MAX(0,(14.4-H18)/(14.4-4.8)*100))) -> 100 | M18: =IFERROR(AVERAGE(J18:L18),"") -> 100
A19: 8edd619d | B19: 홍길동전노래연습장 | C19: 35.175559, 126.914008 | D19: 4 | E19: =TRUE() -> TRUE | G19: 1 | H19: 6.3 | I19: =IF(F19<>"",F19*100,IF(E19=TRUE(),500,"")) -> 500 | J19: =IF(I19="","",MIN(100,MAX(0,(I19-40)/(120-40)*100))) -> 100 | K19: =IF(G19="","",MIN(100,MAX(0,(6-G19)/(6-2)*100))) -> 100 | L19: =IF(H19="","",MIN(100,MAX(0,(14.4-H19)/(14.4-4.8)*100))) -> 84.375 | M19: =IFERROR(AVERAGE(J19:L19),"") -> 94.791667
A20: 96b9f445 | B20: GS25 | C20: 35.177349, 126.913497 | D20: 1 | E20: =TRUE() -> TRUE | G20: 0 | H20: 0 | I20: =IF(F20<>"",F20*100,IF(E20=TRUE(),500,"")) -> 500 | J20: =IF(I20="","",MIN(100,MAX(0,(I20-40)/(120-40)*100))) -> 100 | K20: =IF(G20="","",MIN(100,MAX(0,(6-G20)/(6-2)*100))) -> 100 | L20: =IF(H20="","",MIN(100,MAX(0,(14.4-H20)/(14.4-4.8)*100))) -> 100 | M20: =IFERROR(AVERAGE(J20:L20),"") -> 100
A22: 주: x1_유효폭(cm) = 실측 '유효폭'(m)*100. 실측값이 없고 '유효폭 5m이상'=TRUE인 경우 500cm로 대입(어차피 120cm 이상이면 만점 100으로 클램핑되므로 결과에 영향 없음).

Sheet S2_출입구
A1: ID | B1: 장소명 | C1: GPS | D1: 구역 | E1: 유효폭(m) | F1: 문너비(m) | G1: 이상치제외 | H1: 단차(cm) | I1: 경사로유무 | J1: 기울기(도) | K1: x1_유효폭(cm) | L1: s_width_점수 | M1: s_step_점수(단차) | N1: s_slope_점수(경사로,예외전) | O1: s_step_slope_결합 | P1: S2_출입구지수
A2: 6150c404 | B2: 액티브게임파크 | C2: 35.176241, 126.912605 | D2: 3 | F2: 0.7 | H2: 10.5 | I2: =FALSE() -> FALSE | K2: =IF(E2<>"",E2*100,IF(AND(F2<>"",G2<>"예"),F2*100,"")) -> 70 | L2: =IF(K2="","",MIN(100,MAX(0,(K2-30)/(90-30)*100))) -> 66.666667 | M2: =IF(H2="","",MIN(100,MAX(0,(6-H2)/(6-2)*100))) -> 0 | N2: =IF(H2="","",IF(H2<=2,"",IF(OR(I2=FALSE(),J2=""),0,MIN(100,MAX(0,(14.4-J2)/(14.4-4.8)*100))))) -> 0 | O2: =IF(H2="","",IF(H2<=2,100,0.5*M2+0.5*N2)) -> 0 | P2: =IF(AND(L2<>"",O2<>""),0.5*L2+0.5*O2,"") -> 33.333333
A3: 79ee9d03 | B3: 신데렐라 | C3: 35.175793, 126.913046 | D3: 3 | F3: 0.7 | H3: 10 | I3: =FALSE() -> FALSE | K3: =IF(E3<>"",E3*100,IF(AND(F3<>"",G3<>"예"),F3*100,"")) -> 70 | L3: =IF(K3="","",MIN(100,MAX(0,(K3-30)/(90-30)*100))) -> 66.666667 | M3: =IF(H3="","",MIN(100,MAX(0,(6-H3)/(6-2)*100))) -> 0 | N3: =IF(H3="","",IF(H3<=2,"",IF(OR(I3=FALSE(),J3=""),0,MIN(100,MAX(0,(14.4-J3)/(14.4-4.8)*100))))) -> 0 | O3: =IF(H3="","",IF(H3<=2,100,0.5*M3+0.5*N3)) -> 0 | P3: =IF(AND(L3<>"",O3<>""),0.5*L3+0.5*O3,"") -> 33.333333
A4: a20e38f2 | B4: 미나미 | C4: 35.176844, 126.912660 | D4: 1 | F4: 0.74 | H4: 11 | I4: =FALSE() -> FALSE | K4: =IF(E4<>"",E4*100,IF(AND(F4<>"",G4<>"예"),F4*100,"")) -> 74 | L4: =IF(K4="","",MIN(100,MAX(0,(K4-30)/(90-30)*100))) -> 73.333333 | M4: =IF(H4="","",MIN(100,MAX(0,(6-H4)/(6-2)*100))) -> 0 | N4: =IF(H4="","",IF(H4<=2,"",IF(OR(I4=FALSE(),J4=""),0,MIN(100,MAX(0,(14.4-J4)/(14.4-4.8)*100))))) -> 0 | O4: =IF(H4="","",IF(H4<=2,100,0.5*M4+0.5*N4)) -> 0 | P4: =IF(AND(L4<>"",O4<>""),0.5*L4+0.5*O4,"") -> 36.666667
A5: 536b52b4 | B5: 헤이맨즈 옆 건물 | C5: 35.176864, 126.912991 | D5: 1 | F5: 0.79 | H5: 22 | I5: =FALSE() -> FALSE | K5: =IF(E5<>"",E5*100,IF(AND(F5<>"",G5<>"예"),F5*100,"")) -> 79 | L5: =IF(K5="","",MIN(100,MAX(0,(K5-30)/(90-30)*100))) -> 81.666667 | M5: =IF(H5="","",MIN(100,MAX(0,(6-H5)/(6-2)*100))) -> 0 | N5: =IF(H5="","",IF(H5<=2,"",IF(OR(I5=FALSE(),J5=""),0,MIN(100,MAX(0,(14.4-J5)/(14.4-4.8)*100))))) -> 0 | O5: =IF(H5="","",IF(H5<=2,100,0.5*M5+0.5*N5)) -> 0 | P5: =IF(AND(L5<>"",O5<>""),0.5*L5+0.5*O5,"") -> 40.833333
A6: caab33d8 | B6: Aroundthemoon | C6: 35.176040, 126.913314 | D6: 3 | F6: 0.8 | H6: 10 | I6: =FALSE() -> FALSE | K6: =IF(E6<>"",E6*100,IF(AND(F6<>"",G6<>"예"),F6*100,"")) -> 80 | L6: =IF(K6="","",MIN(100,MAX(0,(K6-30)/(90-30)*100))) -> 83.333333 | M6: =IF(H6="","",MIN(100,MAX(0,(6-H6)/(6-2)*100))) -> 0 | N6: =IF(H6="","",IF(H6<=2,"",IF(OR(I6=FALSE(),J6=""),0,MIN(100,MAX(0,(14.4-J6)/(14.4-4.8)*100))))) -> 0 | O6: =IF(H6="","",IF(H6<=2,100,0.5*M6+0.5*N6)) -> 0 | P6: =IF(AND(L6<>"",O6<>""),0.5*L6+0.5*O6,"") -> 41.666667
A7: ffcdf375 | B7: 더포드 | C7: 35.175930, 126.913373 | D7: 3 | F7: 0.8 | H7: 14 | I7: =FALSE() -> FALSE | K7: =IF(E7<>"",E7*100,IF(AND(F7<>"",G7<>"예"),F7*100,"")) -> 80 | L7: =IF(K7="","",MIN(100,MAX(0,(K7-30)/(90-30)*100))) -> 83.333333 | M7: =IF(H7="","",MIN(100,MAX(0,(6-H7)/(6-2)*100))) -> 0 | N7: =IF(H7="","",IF(H7<=2,"",IF(OR(I7=FALSE(),J7=""),0,MIN(100,MAX(0,(14.4-J7)/(14.4-4.8)*100))))) -> 0 | O7: =IF(H7="","",IF(H7<=2,100,0.5*M7+0.5*N7)) -> 0 | P7: =IF(AND(L7<>"",O7<>""),0.5*L7+0.5*O7,"") -> 41.666667
A8: 2adf219d | B8: 감성상자 그안 | C8: 35.177356, 126.913812 | D8: 2 | F8: 0.8 | H8: 17 | I8: =FALSE() -> FALSE | K8: =IF(E8<>"",E8*100,IF(AND(F8<>"",G8<>"예"),F8*100,"")) -> 80 | L8: =IF(K8="","",MIN(100,MAX(0,(K8-30)/(90-30)*100))) -> 83.333333 | M8: =IF(H8="","",MIN(100,MAX(0,(6-H8)/(6-2)*100))) -> 0 | N8: =IF(H8="","",IF(H8<=2,"",IF(OR(I8=FALSE(),J8=""),0,MIN(100,MAX(0,(14.4-J8)/(14.4-4.8)*100))))) -> 0 | O8: =IF(H8="","",IF(H8<=2,100,0.5*M8+0.5*N8)) -> 0 | P8: =IF(AND(L8<>"",O8<>""),0.5*L8+0.5*O8,"") -> 41.666667
A9: 8f3d4791 | B9: rastar | C9: 35.175598, 126.913708 | D9: 4 | F9: 0.8 | H9: 18 | I9: =FALSE() -> FALSE | K9: =IF(E9<>"",E9*100,IF(AND(F9<>"",G9<>"예"),F9*100,"")) -> 80 | L9: =IF(K9="","",MIN(100,MAX(0,(K9-30)/(90-30)*100))) -> 83.333333 | M9: =IF(H9="","",MIN(100,MAX(0,(6-H9)/(6-2)*100))) -> 0 | N9: =IF(H9="","",IF(H9<=2,"",IF(OR(I9=FALSE(),J9=""),0,MIN(100,MAX(0,(14.4-J9)/(14.4-4.8)*100))))) -> 0 | O9: =IF(H9="","",IF(H9<=2,100,0.5*M9+0.5*N9)) -> 0 | P9: =IF(AND(L9<>"",O9<>""),0.5*L9+0.5*O9,"") -> 41.666667
A10: 959decc9 | B10: 송고집 | C10: 35.177315, 126.913187 | D10: 1 | F10: 0.81 | H10: 16 | I10: =FALSE() -> FALSE | K10: =IF(E10<>"",E10*100,IF(AND(F10<>"",G10<>"예"),F10*100,"")) -> 81 | L10: =IF(K10="","",MIN(100,MAX(0,(K10-30)/(90-30)*100))) -> 85 | M10: =IF(H10="","",MIN(100,MAX(0,(6-H10)/(6-2)*100))) -> 0 | N10: =IF(H10="","",IF(H10<=2,"",IF(OR(I10=FALSE(),J10=""),0,MIN(100,MAX(0,(14.4-J10)/(14.4-4.8)*100))))) -> 0 | O10: =IF(H10="","",IF(H10<=2,100,0.5*M10+0.5*N10)) -> 0 | P10: =IF(AND(L10<>"",O10<>""),0.5*L10+0.5*O10,"") -> 42.5
A11: d954ce54 | B11: BARUK | C11: 35.176752, 126.913502 | D11: 2 | F11: 0.81 | H11: 13 | I11: =FALSE() -> FALSE | K11: =IF(E11<>"",E11*100,IF(AND(F11<>"",G11<>"예"),F11*100,"")) -> 81 | L11: =IF(K11="","",MIN(100,MAX(0,(K11-30)/(90-30)*100))) -> 85 | M11: =IF(H11="","",MIN(100,MAX(0,(6-H11)/(6-2)*100))) -> 0 | N11: =IF(H11="","",IF(H11<=2,"",IF(OR(I11=FALSE(),J11=""),0,MIN(100,MAX(0,(14.4-J11)/(14.4-4.8)*100))))) -> 0 | O11: =IF(H11="","",IF(H11<=2,100,0.5*M11+0.5*N11)) -> 0 | P11: =IF(AND(L11<>"",O11<>""),0.5*L11+0.5*O11,"") -> 42.5
A12: c7a4bd56 | B12: 으뜸안경원 | C12: 35.176389, 126.912865 | D12: 3 | F12: 0.82 | H12: 8 | I12: =FALSE() -> FALSE | K12: =IF(E12<>"",E12*100,IF(AND(F12<>"",G12<>"예"),F12*100,"")) -> 82 | L12: =IF(K12="","",MIN(100,MAX(0,(K12-30)/(90-30)*100))) -> 86.666667 | M12: =IF(H12="","",MIN(100,MAX(0,(6-H12)/(6-2)*100))) -> 0 | N12: =IF(H12="","",IF(H12<=2,"",IF(OR(I12=FALSE(),J12=""),0,MIN(100,MAX(0,(14.4-J12)/(14.4-4.8)*100))))) -> 0 | O12: =IF(H12="","",IF(H12<=2,100,0.5*M12+0.5*N12)) -> 0 | P12: =IF(AND(L12<>"",O12<>""),0.5*L12+0.5*O12,"") -> 43.333333
A13: 2c8253aa | B13: 올리브 | C13: 35.176504, 126.913821 | D13: 2 | F13: 0.82 | H13: 21 | I13: =FALSE() -> FALSE | K13: =IF(E13<>"",E13*100,IF(AND(F13<>"",G13<>"예"),F13*100,"")) -> 82 | L13: =IF(K13="","",MIN(100,MAX(0,(K13-30)/(90-30)*100))) -> 86.666667 | M13: =IF(H13="","",MIN(100,MAX(0,(6-H13)/(6-2)*100))) -> 0 | N13: =IF(H13="","",IF(H13<=2,"",IF(OR(I13=FALSE(),J13=""),0,MIN(100,MAX(0,(14.4-J13)/(14.4-4.8)*100))))) -> 0 | O13: =IF(H13="","",IF(H13<=2,100,0.5*M13+0.5*N13)) -> 0 | P13: =IF(AND(L13<>"",O13<>""),0.5*L13+0.5*O13,"") -> 43.333333
... A22: 4be33085 | B22: 정통집 | C22: 35.176535, 126.913507 | D22: 2 | F22: 0.85 | H22: 12 | I22: =FALSE() -> FALSE | K22: =IF(E22<>"",E22*100,IF(AND(F22<>"",G22<>"예"),F22*100,"")) -> 85 | L22: =IF(K22="","",MIN(100,MAX(0,(K22-30)/(90-30)*100))) -> 91.666667 | M22: =IF(H22="","",MIN(100,MAX(0,(6-H22)/(6-2)*100))) -> 0 | N22: =IF(H22="","",IF(H22<=2,"",IF(OR(I22=FALSE(),J22=""),0,MIN(100,MAX(0,(14.4-J22)/(14.4-4.8)*100))))) -> 0 | O22: =IF(H22="","",IF(H22<=2,100,0.5*M22+0.5*N22)) -> 0 | P22: =IF(AND(L22<>"",O22<>""),0.5*L22+0.5*O22,"") -> 45.833333
A23: 0ced2290 | B23: givemetaco | C23: 35.176368, 126.912599 | D23: 3 | F23: 0.86 | H23: 12.5 | I23: =TRUE() -> TRUE | J23: 18.7 | K23: =IF(E23<>"",E23*100,IF(AND(F23<>"",G23<>"예"),F23*100,"")) -> 86 | L23: =IF(K23="","",MIN(100,MAX(0,(K23-30)/(90-30)*100))) -> 93.333333 | M23: =IF(H23="","",MIN(100,MAX(0,(6-H23)/(6-2)*100))) -> 0 | N23: =IF(H23="","",IF(H23<=2,"",IF(OR(I23=FALSE(),J23=""),0,MIN(100,MAX(0,(14.4-J23)/(14.4-4.8)*100))))) -> 0 | O23: =IF(H23="","",IF(H23<=2,100,0.5*M23+0.5*N23)) -> 0 | P23: =IF(AND(L23<>"",O23<>""),0.5*L23+0.5*O23,"") -> 46.666667
A24: 0b1b1669 | B24: 먹새통 | C24: 35.177008, 126.913814 | D24: 2 | F24: 0.86 | H24: 13 | I24: =FALSE() -> FALSE | K24: =IF(E24<>"",E24*100,IF(AND(F24<>"",G24<>"예"),F24*100,"")) -> 86 | L24: =IF(K24="","",MIN(100,MAX(0,(K24-30)/(90-30)*100))) -> 93.333333 | M24: =IF(H24="","",MIN(100,MAX(0,(6-H24)/(6-2)*100))) -> 0 | N24: =IF(H24="","",IF(H24<=2,"",IF(OR(I24=FALSE(),J24=""),0,MIN(100,MAX(0,(14.4-J24)/(14.4-4.8)*100))))) -> 0 | O24: =IF(H24="","",IF(H24<=2,100,0.5*M24+0.5*N24)) -> 0 | P24: =IF(AND(L24<>"",O24<>""),0.5*L24+0.5*O24,"") -> 46.666667
A25: fd925e84 | B25: 내가찜한닭 | C25: 35.175601, 126.913769 | D25: 4 | F25: 0.86 | H25: 18 | I25: =FALSE() -> FALSE | K25: =IF(E25<>"",E25*100,IF(AND(F25<>"",G25<>"예"),F25*100,"")) -> 86 | L25: =IF(K25="","",MIN(100,MAX(0,(K25-30)/(90-30)*100))) -> 93.333333 | M25: =IF(H25="","",MIN(100,MAX(0,(6-H25)/(6-2)*100))) -> 0 | N25: =IF(H25="","",IF(H25<=2,"",IF(OR(I25=FALSE(),J25=""),0,MIN(100,MAX(0,(14.4-J25)/(14.4-4.8)*100))))) -> 0 | O25: =IF(H25="","",IF(H25<=2,100,0.5*M25+0.5*N25)) -> 0 | P25: =IF(AND(L25<>"",O25<>""),0.5*L25+0.5*O25,"") -> 46.666667
A26: 2f556499 | B26: 인형뽑기 | C26: 35.176422, 126.913604 | D26: 4 | F26: 0.88 | H26: 12 | I26: =FALSE() -> FALSE | K26: =IF(E26<>"",E26*100,IF(AND(F26<>"",G26<>"예"),F26*100,"")) -> 88 | L26: =IF(K26="","",MIN(100,MAX(0,(K26-30)/(90-30)*100))) -> 96.666667 | M26: =IF(H26="","",MIN(100,MAX(0,(6-H26)/(6-2)*100))) -> 0 | N26: =IF(H26="","",IF(H26<=2,"",IF(OR(I26=FALSE(),J26=""),0,MIN(100,MAX(0,(14.4-J26)/(14.4-4.8)*100))))) -> 0 | O26: =IF(H26="","",IF(H26<=2,100,0.5*M26+0.5*N26)) -> 0 | P26: =IF(AND(L26<>"",O26<>""),0.5*L26+0.5*O26,"") -> 48.333333
A27: 4918c91a | B27: 충만치킨 전남대 | C27: 35.177292, 126.912826 | D27: 1 | F27: 0.88 | H27: 11 | I27: =FALSE() -> FALSE | K27: =IF(E27<>"",E27*100,IF(AND(F27<>"",G27<>"예"),F27*100,"")) -> 88 | L27: =IF(K27="","",MIN(100,MAX(0,(K27-30)/(90-30)*100))) -> 96.666667 | M27: =IF(H27="","",MIN(100,MAX(0,(6-H27)/(6-2)*100))) -> 0 | N27: =IF(H27="","",IF(H27<=2,"",IF(OR(I27=FALSE(),J27=""),0,MIN(100,MAX(0,(14.4-J27)/(14.4-4.8)*100))))) -> 0 | O27: =IF(H27="","",IF(H27<=2,100,0.5*M27+0.5*N27)) -> 0 | P27: =IF(AND(L27<>"",O27<>""),0.5*L27+0.5*O27,"") -> 48.333333
A28: e6311270 | B28: 24시무인빵집 | C28: 35.176477, 126.912891 | D28: 3 | F28: 0.88 | H28: 13 | I28: =FALSE() -> FALSE | K28: =IF(E28<>"",E28*100,IF(AND(F28<>"",G28<>"예"),F28*100,"")) -> 88 | L28: =IF(K28="","",MIN(100,MAX(0,(K28-30)/(90-30)*100))) -> 96.666667 | M28: =IF(H28="","",MIN(100,MAX(0,(6-H28)/(6-2)*100))) -> 0 | N28: =IF(H28="","",IF(H28<=2,"",IF(OR(I28=FALSE(),J28=""),0,MIN(100,MAX(0,(14.4-J28)/(14.4-4.8)*100))))) -> 0 | O28: =IF(H28="","",IF(H28<=2,100,0.5*M28+0.5*N28)) -> 0 | P28: =IF(AND(L28<>"",O28<>""),0.5*L28+0.5*O28,"") -> 48.333333
A29: 41b21d74 | B29: 24시진국 | C29: 35.176770, 126.913630 | D29: 2 | F29: 0.88 | H29: 13 | I29: =FALSE() -> FALSE | K29: =IF(E29<>"",E29*100,IF(AND(F29<>"",G29<>"예"),F29*100,"")) -> 88 | L29: =IF(K29="","",MIN(100,MAX(0,(K29-30)/(90-30)*100))) -> 96.666667 | M29: =IF(H29="","",MIN(100,MAX(0,(6-H29)/(6-2)*100))) -> 0 | N29: =IF(H29="","",IF(H29<=2,"",IF(OR(I29=FALSE(),J29=""),0,MIN(100,MAX(0,(14.4-J29)/(14.4-4.8)*100))))) -> 0 | O29: =IF(H29="","",IF(H29<=2,100,0.5*M29+0.5*N29)) -> 0 | P29: =IF(AND(L29<>"",O29<>""),0.5*L29+0.5*O29,"") -> 48.333333
A30: db25e1c5 | B30: 이자카야 토라 | C30: 35.176904, 126.914003 | D30: 2 | F30: 0.88 | H30: 13 | I30: =FALSE() -> FALSE | K30: =IF(E30<>"",E30*100,IF(AND(F30<>"",G30<>"예"),F30*100,"")) -> 88 | L30: =IF(K30="","",MIN(100,MAX(0,(K30-30)/(90-30)*100))) -> 96.666667 | M30: =IF(H30="","",MIN(100,MAX(0,(6-H30)/(6-2)*100))) -> 0 | N30: =IF(H30="","",IF(H30<=2,"",IF(OR(I30=FALSE(),J30=""),0,MIN(100,MAX(0,(14.4-J30)/(14.4-4.8)*100))))) -> 0 | O30: =IF(H30="","",IF(H30<=2,100,0.5*M30+0.5*N30)) -> 0 | P30: =IF(AND(L30<>"",O30<>""),0.5*L30+0.5*O30,"") -> 48.333333
A31: d6812ebb | B31: 스크린야구장 | C31: 35.176441, 126.913841 | D31: 4 | F31: 0.89 | H31: 12 | I31: =FALSE() -> FALSE | K31: =IF(E31<>"",E31*100,IF(AND(F31<>"",G31<>"예"),F31*100,"")) -> 89 | L31: =IF(K31="","",MIN(100,MAX(0,(K31-30)/(90-30)*100))) -> 98.333333 | M31: =IF(H31="","",MIN(100,MAX(0,(6-H31)/(6-2)*100))) -> 0 | N31: =IF(H31="","",IF(H31<=2,"",IF(OR(I31=FALSE(),J31=""),0,MIN(100,MAX(0,(14.4-J31)/(14.4-4.8)*100))))) -> 0 | O31: =IF(H31="","",IF(H31<=2,100,0.5*M31+0.5*N31)) -> 0 | P31: =IF(AND(L31<>"",O31<>""),0.5*L31+0.5*O31,"") -> 49.166667
A32: 46a25c52 | B32: 에스 | C32: 35.176469, 126.912816 | D32: 3 | F32: 0.89 | H32: 7 | I32: =FALSE() -> FALSE | K32: =IF(E32<>"",E32*100,IF(AND(F32<>"",G32<>"예"),F32*100,"")) -> 89 | L32: =IF(K32="","",MIN(100,MAX(0,(K32-30)/(90-30)*100))) -> 98.333333 | M32: =IF(H32="","",MIN(100,MAX(0,(6-H32)/(6-2)*100))) -> 0 | N32: =IF(H32="","",IF(H32<=2,"",IF(OR(I32=FALSE(),J32=""),0,MIN(100,MAX(0,(14.4-J32)/(14.4-4.8)*100))))) -> 0 | O32: =IF(H32="","",IF(H32<=2,100,0.5*M32+0.5*N32)) -> 0 | P32: =IF(AND(L32<>"",O32<>""),0.5*L32+0.5*O32,"") -> 49.166667
A33: a4f70932 | B33: 참돈 | C33: 35.176910, 126.913883 | D33: 2 | F33: 0.89 | H33: 8 | I33: =FALSE() -> FALSE | K33: =IF(E33<>"",E33*100,IF(AND(F33<>"",G33<>"예"),F33*100,"")) -> 89 | L33: =IF(K33="","",MIN(100,MAX(0,(K33-30)/(90-30)*100))) -> 98.333333 | M33: =IF(H33="","",MIN(100,MAX(0,(6-H33)/(6-2)*100))) -> 0 | N33: =IF(H33="","",IF(H33<=2,"",IF(OR(I33=FALSE(),J33=""),0,MIN(100,MAX(0,(14.4-J33)/(14.4-4.8)*100))))) -> 0 | O33: =IF(H33="","",IF(H33<=2,100,0.5*M33+0.5*N33)) -> 0 | P33: =IF(AND(L33<>"",O33<>""),0.5*L33+0.5*O33,"") -> 49.166667
A34: 93bb6f1f | B34: 데일리키페 | C34: 35.176905, 126.913919 | D34: 2 | F34: 0.89 | H34: 12 | I34: =FALSE() -> FALSE | K34: =IF(E34<>"",E34*100,IF(AND(F34<>"",G34<>"예"),F34*100,"")) -> 89 | L34: =IF(K34="","",MIN(100,MAX(0,(K34-30)/(90-30)*100))) -> 98.333333 | M34: =IF(H34="","",MIN(100,MAX(0,(6-H34)/(6-2)*100))) -> 0 | N34: =IF(H34="","",IF(H34<=2,"",IF(OR(I34=FALSE(),J34=""),0,MIN(100,MAX(0,(14.4-J34)/(14.4-4.8)*100))))) -> 0 | O34: =IF(H34="","",IF(H34<=2,100,0.5*M34+0.5*N34)) -> 0 | P34: =IF(AND(L34<>"",O34<>""),0.5*L34+0.5*O34,"") -> 49.166667
A35: cba47ea3 | B35: 질러질러노래연습장 | C35: 35.176848, 126.914402 | D35: 2 | F35: 0.89 | H35: 17 | I35: =FALSE() -> FALSE | K35: =IF(E35<>"",E35*100,IF(AND(F35<>"",G35<>"예"),F35*100,"")) -> 89 | L35: =IF(K35="","",MIN(100,MAX(0,(K35-30)/(90-30)*100))) -> 98.333333 | M35: =IF(H35="","",MIN(100,MAX(0,(6-H35)/(6-2)*100))) -> 0 | N35: =IF(H35="","",IF(H35<=2,"",IF(OR(I35=FALSE(),J35=""),0,MIN(100,MAX(0,(14.4-J35)/(14.4-4.8)*100))))) -> 0 | O35: =IF(H35="","",IF(H35<=2,100,0.5*M35+0.5*N35)) -> 0 | P35: =IF(AND(L35<>"",O35<>""),0.5*L35+0.5*O35,"") -> 49.166667
... A37: 53d647f8 | B37: 야구사격장 | C37: 35.176380, 126.912782 | D37: 3 | F37: 1.03 | H37: 12 | I37: =FALSE() -> FALSE | K37: =IF(E37<>"",E37*100,IF(AND(F37<>"",G37<>"예"),F37*100,"")) -> 103 | L37: =IF(K37="","",MIN(100,MAX(0,(K37-30)/(90-30)*100))) -> 100 | M37: =IF(H37="","",MIN(100,MAX(0,(6-H37)/(6-2)*100))) -> 0 | N37: =IF(H37="","",IF(H37<=2,"",IF(OR(I37=FALSE(),J37=""),0,MIN(100,MAX(0,(14.4-J37)/(14.4-4.8)*100))))) -> 0 | O37: =IF(H37="","",IF(H37<=2,100,0.5*M37+0.5*N37)) -> 0 | P37: =IF(AND(L37<>"",O37<>""),0.5*L37+0.5*O37,"") -> 50
A38: 6b6fd9dc | B38: 이삭토스트 | C38: 35.176304, 126.912601 | D38: 3 | F38: 1 | H38: 19 | I38: =TRUE() -> TRUE | J38: 16.8 | K38: =IF(E38<>"",E38*100,IF(AND(F38<>"",G38<>"예"),F38*100,"")) -> 100 | L38: =IF(K38="","",MIN(100,MAX(0,(K38-30)/(90-30)*100))) -> 100 | M38: =IF(H38="","",MIN(100,MAX(0,(6-H38)/(6-2)*100))) -> 0 | N38: =IF(H38="","",IF(H38<=2,"",IF(OR(I38=FALSE(),J38=""),0,MIN(100,MAX(0,(14.4-J38)/(14.4-4.8)*100))))) -> 0 | O38: =IF(H38="","",IF(H38<=2,100,0.5*M38+0.5*N38)) -> 0 | P38: =IF(AND(L38<>"",O38<>""),0.5*L38+0.5*O38,"") -> 50
A39: 72564ff1 | B39: MAMMOTH | C39: 35.176839, 126.912527 | D39: 1 | F39: 1.22 | H39: 14 | I39: =FALSE() -> FALSE | K39: =IF(E39<>"",E39*100,IF(AND(F39<>"",G39<>"예"),F39*100,"")) -> 122 | L39: =IF(K39="","",MIN(100,MAX(0,(K39-30)/(90-30)*100))) -> 100 | M39: =IF(H39="","",MIN(100,MAX(0,(6-H39)/(6-2)*100))) -> 0 | N39: =IF(H39="","",IF(H39<=2,"",IF(OR(I39=FALSE(),J39=""),0,MIN(100,MAX(0,(14.4-J39)/(14.4-4.8)*100))))) -> 0 | O39: =IF(H39="","",IF(H39<=2,100,0.5*M39+0.5*N39)) -> 0 | P39: =IF(AND(L39<>"",O39<>""),0.5*L39+0.5*O39,"") -> 50
A40: ebfbf630 | B40: 선경통신 | C40: 35.176876, 126.912514 | D40: 1 | F40: 0.91 | H40: 10 | I40: =FALSE() -> FALSE | K40: =IF(E40<>"",E40*100,IF(AND(F40<>"",G40<>"예"),F40*100,"")) -> 91 | L40: =IF(K40="","",MIN(100,MAX(0,(K40-30)/(90-30)*100))) -> 100 | M40: =IF(H40="","",MIN(100,MAX(0,(6-H40)/(6-2)*100))) -> 0 | N40: =IF(H40="","",IF(H40<=2,"",IF(OR(I40=FALSE(),J40=""),0,MIN(100,MAX(0,(14.4-J40)/(14.4-4.8)*100))))) -> 0 | O40: =IF(H40="","",IF(H40<=2,100,0.5*M40+0.5*N40)) -> 0 | P40: =IF(AND(L40<>"",O40<>""),0.5*L40+0.5*O40,"") -> 50
A41: 27840150 | B41: GONG cha | C41: 35.176945, 126.912506 | D41: 1 | F41: 1.81 | H41: 14 | I41: =FALSE() -> FALSE | K41: =IF(E41<>"",E41*100,IF(AND(F41<>"",G41<>"예"),F41*100,"")) -> 181 | L41: =IF(K41="","",MIN(100,MAX(0,(K41-30)/(90-30)*100))) -> 100 | M41: =IF(H41="","",MIN(100,MAX(0,(6-H41)/(6-2)*100))) -> 0 | N41: =IF(H41="","",IF(H41<=2,"",IF(OR(I41=FALSE(),J41=""),0,MIN(100,MAX(0,(14.4-J41)/(14.4-4.8)*100))))) -> 0 | O41: =IF(H41="","",IF(H41<=2,100,0.5*M41+0.5*N41)) -> 0 | P41: =IF(AND(L41<>"",O41<>""),0.5*L41+0.5*O41,"") -> 50
A42: 2621a1cf | B42: skt대리점 | C42: 35.176208, 126.912618 | D42: 3 | F42: 1.8 | H42: 17 | I42: =FALSE() -> FALSE | K42: =IF(E42<>"",E42*100,IF(AND(F42<>"",G42<>"예"),F42*100,"")) -> 180 | L42: =IF(K42="","",MIN(100,MAX(0,(K42-30)/(90-30)*100))) -> 100 | M42: =IF(H42="","",MIN(100,MAX(0,(6-H42)/(6-2)*100))) -> 0 | N42: =IF(H42="","",IF(H42<=2,"",IF(OR(I42=FALSE(),J42=""),0,MIN(100,MAX(0,(14.4-J42)/(14.4-4.8)*100))))) -> 0 | O42: =IF(H42="","",IF(H42<=2,100,0.5*M42+0.5*N42)) -> 0 | P42: =IF(AND(L42<>"",O42<>""),0.5*L42+0.5*O42,"") -> 50
A43: 1c05aa16 | B43: WEVAPE전대전담 | C43: 35.177060, 126.912487 | D43: 1 | F43: 1 | H43: 22 | I43: =FALSE() -> FALSE | K43: =IF(E43<>"",E43*100,IF(AND(F43<>"",G43<>"예"),F43*100,"")) -> 100 | L43: =IF(K43="","",MIN(100,MAX(0,(K43-30)/(90-30)*100))) -> 100 | M43: =IF(H43="","",MIN(100,MAX(0,(6-H43)/(6-2)*100))) -> 0 | N43: =IF(H43="","",IF(H43<=2,"",IF(OR(I43=FALSE(),J43=""),0,MIN(100,MAX(0,(14.4-J43)/(14.4-4.8)*100))))) -> 0 | O43: =IF(H43="","",IF(H43<=2,100,0.5*M43+0.5*N43)) -> 0 | P43: =IF(AND(L43<>"",O43<>""),0.5*L43+0.5*O43,"") -> 50
A44: aa8d6c41 | B44: 통통 탕후루,타코야끼 | C44: 35.177082, 126.912477 | D44: 1 | F44: 0.9 | H44: 21 | I44: =FALSE() -> FALSE | K44: =IF(E44<>"",E44*100,IF(AND(F44<>"",G44<>"예"),F44*100,"")) -> 90 | L44: =IF(K44="","",MIN(100,MAX(0,(K44-30)/(90-30)*100))) -> 100 | M44: =IF(H44="","",MIN(100,MAX(0,(6-H44)/(6-2)*100))) -> 0 | N44: =IF(H44="","",IF(H44<=2,"",IF(OR(I44=FALSE(),J44=""),0,MIN(100,MAX(0,(14.4-J44)/(14.4-4.8)*100))))) -> 0 | O44: =IF(H44="","",IF(H44<=2,100,0.5*M44+0.5*N44)) -> 0 | P44: =IF(AND(L44<>"",O44<>""),0.5*L44+0.5*O44,"") -> 50
A45: c2e3f18f | B45: 육회바른연어 | C45: 35.176107, 126.912634 | D45: 3 | F45: 0.9 | H45: 25 | I45: =FALSE() -> FALSE | K45: =IF(E45<>"",E45*100,IF(AND(F45<>"",G45<>"예"),F45*100,"")) -> 90 | L45: =IF(K45="","",MIN(100,MAX(0,(K45-30)/(90-30)*100))) -> 100 | M45: =IF(H45="","",MIN(100,MAX(0,(6-H45)/(6-2)*100))) -> 0 | N45: =IF(H45="","",IF(H45<=2,"",IF(OR(I45=FALSE(),J45=""),0,MIN(100,MAX(0,(14.4-J45)/(14.4-4.8)*100))))) -> 0 | O45: =IF(H45="","",IF(H45<=2,100,0.5*M45+0.5*N45)) -> 0 | P45: =IF(AND(L45<>"",O45<>""),0.5*L45+0.5*O45,"") -> 50
A46: 98fb4b60 | B46: UPRIGHT | C46: 35.177108, 126.912474 | D46: 1 | F46: 1.05 | H46: 21 | I46: =FALSE() -> FALSE | K46: =IF(E46<>"",E46*100,IF(AND(F46<>"",G46<>"예"),F46*100,"")) -> 105 | L46: =IF(K46="","",MIN(100,MAX(0,(K46-30)/(90-30)*100))) -> 100 | M46: =IF(H46="","",MIN(100,MAX(0,(6-H46)/(6-2)*100))) -> 0 | N46: =IF(H46="","",IF(H46<=2,"",IF(OR(I46=FALSE(),J46=""),0,MIN(100,MAX(0,(14.4-J46)/(14.4-4.8)*100))))) -> 0 | O46: =IF(H46="","",IF(H46<=2,100,0.5*M46+0.5*N46)) -> 0 | P46: =IF(AND(L46<>"",O46<>""),0.5*L46+0.5*O46,"") -> 50
A47: cc7f6429 | B47: 피엔스튜디오 | C47: 35.176411, 126.913321 | D47: 3 | F47: 0.93 | H47: 16 | I47: =FALSE() -> FALSE | K47: =IF(E47<>"",E47*100,IF(AND(F47<>"",G47<>"예"),F47*100,"")) -> 93 | L47: =IF(K47="","",MIN(100,MAX(0,(K47-30)/(90-30)*100))) -> 100 | M47: =IF(H47="","",MIN(100,MAX(0,(6-H47)/(6-2)*100))) -> 0 | N47: =IF(H47="","",IF(H47<=2,"",IF(OR(I47=FALSE(),J47=""),0,MIN(100,MAX(0,(14.4-J47)/(14.4-4.8)*100))))) -> 0 | O47: =IF(H47="","",IF(H47<=2,100,0.5*M47+0.5*N47)) -> 0 | P47: =IF(AND(L47<>"",O47<>""),0.5*L47+0.5*O47,"") -> 50
A48: 8ec70409 | B48: LENS ME | C48: 35.176074, 126.912632 | D48: 3 | F48: 1.1 | H48: 23 | I48: =FALSE() -> FALSE | K48: =IF(E48<>"",E48*100,IF(AND(F48<>"",G48<>"예"),F48*100,"")) -> 110 | L48: =IF(K48="","",MIN(100,MAX(0,(K48-30)/(90-30)*100))) -> 100 | M48: =IF(H48="","",MIN(100,MAX(0,(6-H48)/(6-2)*100))) -> 0 | N48: =IF(H48="","",IF(H48<=2,"",IF(OR(I48=FALSE(),J48=""),0,MIN(100,MAX(0,(14.4-J48)/(14.4-4.8)*100))))) -> 0 | O48: =IF(H48="","",IF(H48<=2,100,0.5*M48+0.5*N48)) -> 0 | P48: =IF(AND(L48<>"",O48<>""),0.5*L48+0.5*O48,"") -> 50
A49: 112376db | B49: 전담성지 | C49: 35.175914, 126.912656 | D49: 3 | F49: 1 | H49: 17.5 | I49: =FALSE() -> FALSE | K49: =IF(E49<>"",E49*100,IF(AND(F49<>"",G49<>"예"),F49*100,"")) -> 100 | L49: =IF(K49="","",MIN(100,MAX(0,(K49-30)/(90-30)*100))) -> 100 | M49: =IF(H49="","",MIN(100,MAX(0,(6-H49)/(6-2)*100))) -> 0 | N49: =IF(H49="","",IF(H49<=2,"",IF(OR(I49=FALSE(),J49=""),0,MIN(100,MAX(0,(14.4-J49)/(14.4-4.8)*100))))) -> 0 | O49: =IF(H49="","",IF(H49<=2,100,0.5*M49+0.5*N49)) -> 0 | P49: =IF(AND(L49<>"",O49<>""),0.5*L49+0.5*O49,"") -> 50
...

Sheet 구역별_Sn_집계
A1: 구역 | B1: S1_보행로(실측평균) | C1: S2_출입구(실측평균) | D1: S3_화장실(가정값) | E1: S4_엘리베이터(가정값) | F1: S5_주차장(가정값) | G1: S1_측정지점수 | H1: S2_측정지점수
A2: 1 | B2: =IFERROR(AVERAGEIF(S1_보행로!$D$2:$D$20,A2,S1_보행로!$M$2:$M$20),"N/A") -> 87.615741 | C2: =IFERROR(AVERAGEIF(S2_출입구!$D$2:$D$205,A2,S2_출입구!$P$2:$P$205),"N/A") -> 60.838415 | D2: =가정_및_설정!$B$2 -> 50 | E2: =가정_및_설정!$B$3 -> 50 | F2: =가정_및_설정!$B$4 -> 50 | G2: =COUNTIF(S1_보행로!$D$2:$D$20,A2) -> 6 | H2: =COUNTIF(S2_출입구!$D$2:$D$205,A2) -> 41
A3: 2 | B3: =IFERROR(AVERAGEIF(S1_보행로!$D$2:$D$20,A3,S1_보행로!$M$2:$M$20),"N/A") -> 100 | C3: =IFERROR(AVERAGEIF(S2_출입구!$D$2:$D$205,A3,S2_출입구!$P$2:$P$205),"N/A") -> 55.007716 | D3: =가정_및_설정!$B$2 -> 50 | E3: =가정_및_설정!$B$3 -> 50 | F3: =가정_및_설정!$B$4 -> 50 | G3: =COUNTIF(S1_보행로!$D$2:$D$20,A3) -> 3 | H3: =COUNTIF(S2_출입구!$D$2:$D$205,A3) -> 57
A4: 3 | B4: =IFERROR(AVERAGEIF(S1_보행로!$D$2:$D$20,A4,S1_보행로!$M$2:$M$20),"N/A") -> 100 | C4: =IFERROR(AVERAGEIF(S2_출입구!$D$2:$D$205,A4,S2_출입구!$P$2:$P$205),"N/A") -> 51.799546 | D4: =가정_및_설정!$B$2 -> 50 | E4: =가정_및_설정!$B$3 -> 50 | F4: =가정_및_설정!$B$4 -> 50 | G4: =COUNTIF(S1_보행로!$D$2:$D$20,A4) -> 5 | H4: =COUNTIF(S2_출입구!$D$2:$D$205,A4) -> 78
A5: 4 | B5: =IFERROR(AVERAGEIF(S1_보행로!$D$2:$D$20,A5,S1_보행로!$M$2:$M$20),"N/A") -> 98.958333 | C5: =IFERROR(AVERAGEIF(S2_출입구!$D$2:$D$205,A5,S2_출입구!$P$2:$P$205),"N/A") -> 52.726935 | D5: =가정_및_설정!$B$2 -> 50 | E5: =가정_및_설정!$B$3 -> 50 | F5: =가정_및_설정!$B$4 -> 50 | G5: =COUNTIF(S1_보행로!$D$2:$D$20,A5) -> 5 | H5: =COUNTIF(S2_출입구!$D$2:$D$205,A5) -> 28
A7: 주: S3~S5는 실측 데이터가 없어 '가정_및_설정' 시트의 지정값(50점)을 모든 구역에 동일 대입함(사용자 확인 완료).

Sheet 구역별_최종지수
A1: 구역 | B1: S1 | C1: S2 | D1: S3 | E1: S4 | F1: S5 | G1: 최종_넓이_지수(Final Index)
A2: 1 | B2: =구역별_Sn_집계!B2 -> 87.615741 | C2: =구역별_Sn_집계!C2 -> 60.838415 | D2: =구역별_Sn_집계!D2 -> 50 | E2: =구역별_Sn_집계!E2 -> 50 | F2: =구역별_Sn_집계!F2 -> 50 | G2: =(B2*C2+C2*D2+D2*E2+E2*F2+F2*B2)/(5*10000)*100 -> 35.506221
A3: 2 | B3: =구역별_Sn_집계!B3 -> 100 | C3: =구역별_Sn_집계!C3 -> 55.007716 | D3: =구역별_Sn_집계!D3 -> 50 | E3: =구역별_Sn_집계!E3 -> 50 | F3: =구역별_Sn_집계!F3 -> 50 | G3: =(B3*C3+C3*D3+D3*E3+E3*F3+F3*B3)/(5*10000)*100 -> 36.502315
A4: 3 | B4: =구역별_Sn_집계!B4 -> 100 | C4: =구역별_Sn_집계!C4 -> 51.799546 | D4: =구역별_Sn_집계!D4 -> 50 | E4: =구역별_Sn_집계!E4 -> 50 | F4: =구역별_Sn_집계!F4 -> 50 | G4: =(B4*C4+C4*D4+D4*E4+E4*F4+F4*B4)/(5*10000)*100 -> 35.539864
A5: 4 | B5: =구역별_Sn_집계!B5 -> 98.958333 | C5: =구역별_Sn_집계!C5 -> 52.726935 | D5: =구역별_Sn_집계!D5 -> 50 | E5: =구역별_Sn_집계!E5 -> 50 | F5: =구역별_Sn_집계!F5 -> 50 | G5: =(B5*C5+C5*D5+D5*E5+E5*F5+F5*B5)/(5*10000)*100 -> 35.604066
A7: ※ 공식 출처: 카테고리_점수화_공식.pdf ② 최종 넓이 지수(Result Index) - 5개 카테고리(S1~S5) 오각형 순환곱 공식을 그대로 사용함(PDF에 명시된 고정 공식, n=5 확장 불필요).
A8: ※ S3(화장실)/S4(엘리베이터)/S5(주차장)는 실측 데이터가 전무하여 사용자 지정 임시값(50점)을 대입해 산출한 결과이며, 추후 실측 데이터가 확보되면 반드시 재계산이 필요함.
